<mujoco model="humanoid">
    <compiler angle="degree" inertiafromgeom="true"/>
    <default>
        <joint armature="1" damping="1" limited="true"/>
        <geom conaffinity="1" condim="1" contype="1" margin="0.001" material="geom" rgba="0.8 0.6 .4 1"/>
        <motor ctrllimited="true" ctrlrange="-.4 .4"/>
    </default>
    <option integrator="RK4" iterations="50" solver="PGS" timestep="0.003">
        <!-- <flags solverstat="enable" energy="enable"/>-->
    </option>
    <size nkey="5" nuser_geom="1"/>
    <visual>
        <map fogend="5" fogstart="3"/>
    </visual>
    <asset>
        <texture builtin="gradient" height="100" rgb1=".4 .5 .6" rgb2="0 0 0" type="skybox" width="100"/>
        <!-- <texture builtin="gradient" height="100" rgb1="1 1 1" rgb2="0 0 0" type="skybox" width="100"/>-->
        <texture builtin="flat" height="1278" mark="cross" markrgb="1 1 1" name="texgeom" random="0.01" rgb1="0.8 0.6 0.4" rgb2="0.8 0.6 0.4" type="cube" width="127"/>
        <texture builtin="checker" height="100" name="texplane" rgb1="0 0 0" rgb2="0.8 0.8 0.8" type="2d" width="100"/>
        <material name="MatPlane" reflectance="0.5" shininess="1" specular="1" texrepeat="60 60" texture="texplane"/>
        <material name="geom" texture="texgeom" texuniform="true"/>
    </asset>
    <worldbody>
       <body name="root" pos="0.0 0.0 0.89">
	         <!--<joint armature="0.01" axis="1 0 0" damping="5" name="root_x" pos="0.0 0.0 0.0" range="-15 15" stiffness="10" type="free"/>-->
             <geom name="root" type="box" pos="0.0 0.0 0.0" size="0.01 0.01 0.01"  mass="0.01"/>
			 <body name="pelvis" pos="0.0 0.0 0.0">
	             <joint armature="10000.0" axis="1 0 0" damping="5" name="pelvis_x" pos="0.0 0.0 0.0" range="-0.00001 0.00001" stiffness="1000000" type="hinge"/>
                 <geom name="pelvis" type="box" pos="0.0 0.0 0.03" size="0.06 0.135 0.075"  mass="10.0"/> 
			 </body>
			 <!--<joint armature="0.01" axis="1 0 0" damping="5" name="pervis_join" pos="0.0 0.0 0.0" range="-0.0 0.0" stiffness="1000" type="hinge"/>-->
		     <body name="torso" pos="0.0 0.0 0.10" user="128">
			     <joint armature="0.01" axis="1 0 0" damping="5" name="abdomen_x" pos="0.0 0.0 0.0" range="-15 15" stiffness="10" type="hinge"/>
                 <joint armature="0.01" axis="0 1 0" damping="5" name="abdomen_y" pos="0.0 0.0 0.0" range="0 30" stiffness="10" type="hinge"/>
                 <joint armature="0.01" axis="0 0 1" damping="5" name="abdomen_z" pos="0.0 0.0 0.0" range="-45 45" stiffness="20" type="hinge"/>
                 <geom name="torso" type="box"  pos= "0.0 0.0 0.17" size="0.065 0.145 0.165" mass="15.0"/>
			</body>
		   		   
			<body name="right_thigh" pos="0.0 -0.085 0.0">
                <joint armature="0.01" axis="1 0 0" damping="5" name="right_hip_x" pos="0.0 0.0 0.0" range="-45 0" stiffness="10" type="hinge"/>
                <joint armature="0.01" axis="0 1 0" damping="5" name="right_hip_y" pos="0.0 0.0 0.0" range="-120 60" stiffness="20" type="hinge"/>
                <joint armature="0.01" axis="0 0 1" damping="5" name="right_hip_z" pos="0.0 0.0 0.0" range="-45 45" stiffness="10" type="hinge"/>
                <geom name="right_thigh" type="box" pos="0.0 0.0 -0.21075" size="0.045 0.045 0.21075"  mass="4.5"/>        
                <body name="right_knee" pos="0.0 0.0 -0.4215">
                    <joint armature="0.010" axis="0 -1 0" name="right_knee" pos="0.0 0.0 0.0" range="-110 0" type="hinge"/>
					<geom name="right_knee" type="box" pos="0.0 0.0 -0.19493" size="0.035 0.035 0.215"  mass="3.0"/>
                    <body name="right_foot" pos="0.0 0.0 -0.40987">
                        <joint armature="0.0030" axis="1 0 0" name="right_ankle_x" pos="0.0 0.0 0.0" range="-30 30" type="hinge"/>
                        <joint armature="0.0030" axis="0 1 0" name="right_ankle_y" pos="0.0 0.0 0.0" range="-50 30" type="hinge"/>
                        <joint armature="0.0030" axis="0 0 1" name="right_ankle_z" pos="0.0 0.0 0.0" range="-30 30" type="hinge"/>
                        <geom name="right_foot" pos="0.0518 0.0 -0.0224" size="0.0885 0.045 0.025" type="box" user="0" mass="1.0"/>
                    </body>
                </body>
            </body>		   
			
		   <body name="left_thigh" pos="0.0 0.085 0.0">
                <joint armature="0.01" axis="1 0 0" damping="5" name="left_hip_x" pos="0.0 0.0 0.0" range="-45 0" stiffness="10" type="hinge"/>
                <joint armature="0.01" axis="0 1 0" damping="5" name="left_hip_y" pos="0.0 0.0 0.0" range="-120 60" stiffness="20" type="hinge"/>
                <joint armature="0.01" axis="0 0 1" damping="5" name="left_hip_z" pos="0.0 0.0 0.0" range="-45 45" stiffness="10" type="hinge"/>
                <geom name="left_thigh" type="box" pos="0.0 0.0 -0.21075" size="0.045 0.045 0.21075"  mass="4.5"/>        
                <body name="left_knee" pos="0.0 0.0  -0.4215">
                    <joint armature="0.010" axis="0 -1 0" name="left_knee" pos="0.0 0.0 0.0" range="-110 0" type="hinge"/>
					<geom name="left_knee" type="box" pos="0.0 0.0 -0.19493" size="0.035 0.035 0.215"  mass="3.0"/>
                    <body name="left_foot" pos="0.0 0.0 -0.40987">
                        <joint armature="0.0030" axis="1 0 0" name="left_ankle_x" pos="0.0 0.0 0.0" range="-30 30" type="hinge"/>
                        <joint armature="0.0030" axis="0 1 0" name="left_ankle_y" pos="0.0 0.0 0.0" range="-50 30" type="hinge"/>
                        <joint armature="0.0030" axis="0 0 1" name="left_ankle_z" pos="0.0 0.0 0.0" range="-30 30" type="hinge"/>
                        <geom name="left_foot" pos="0.0518 0.0 -0.0224" size="0.0885 0.045  0.025" type="box" user="0" mass="1.0"/>
                    </body>
                </body>
            </body>		   
        </body>
			
       <!-- </body>-->
	    <!--</body>-->
    </worldbody>

    <tendon>
        <fixed name="left_hipknee">
            <joint coef="-1" joint="left_hip_y"/>
            <joint coef="1" joint="left_knee"/>
        </fixed>
        <fixed name="right_hipknee">
            <joint coef="-1" joint="right_hip_y"/>
            <joint coef="1" joint="right_knee"/>
        </fixed>
    </tendon>
    
    <!--<actuator>
        <motor gear="100" joint="neck_x" name="neck_x"/>
        <motor gear="100" joint="neck_y" name="neck_y"/>
        <motor gear="100" joint="neck_z" name="neck_z"/>
        <motor gear="100" joint="abdomen_x" name="abdomen_x"/>
        <motor gear="100" joint="abdomen_y" name="abdomen_y"/>
        <motor gear="100" joint="abdomen_z" name="abdomen_z"/>
        <motor gear="150" joint="right_hip_x" name="right_hip_x"/>
        <motor gear="300" joint="right_hip_y" name="right_hip_y"/>
        <motor gear="100" joint="right_hip_z" name="right_hip_z"/>
        <motor gear="100" joint="right_knee" name="right_knee"/>
        <motor gear="25" joint="right_ankle_x" name="right_ankle_x"/>
        <motor gear="25" joint="right_ankle_y" name="right_ankle_y"/>
        <motor gear="25" joint="right_ankle_z" name="right_ankle_z"/>
        <motor gear="150" joint="left_hip_x" name="left_hip_x"/>
        <motor gear="300" joint="left_hip_y" name="left_hip_y"/>
        <motor gear="100" joint="left_hip_z" name="left_hip_z"/>
        <motor gear="100" joint="left_knee" name="left_knee"/>
        <motor gear="25" joint="left_ankle_x" name="left_ankle_x"/>
        <motor gear="25" joint="left_ankle_y" name="left_ankle_y"/>
        <motor gear="25" joint="left_ankle_z" name="left_ankle_z"/>
    </actuator>-->
</mujoco>


